#VRML_SIM R2023a utf8

EXTERNPROTO "https://raw.githubusercontent.com/cyberbotics/webots/R2023a/projects/objects/backgrounds/protos/TexturedBackground.proto"
EXTERNPROTO "https://raw.githubusercontent.com/cyberbotics/webots/R2023a/projects/objects/backgrounds/protos/TexturedBackgroundLight.proto"
EXTERNPROTO "https://raw.githubusercontent.com/cyberbotics/webots/R2023a/projects/objects/floors/protos/RectangleArena.proto"

WorldInfo {
  contactProperties [
    ContactProperties {
      coulombFriction [
        3
      ]
    }
  ]
}
Viewpoint {
  orientation -0.0840368327785987 0.017702123329704417 0.9963053977401517 2.7278929678113055
  position 0.31620941040025474 -0.040026603264391156 0.09993836573057555
}
TexturedBackground {
}
TexturedBackgroundLight {
}
RectangleArena {
}
Robot {
  translation 0.03042719520644083 0.09472089788583447 -3.796361276515309e-05
  rotation -0.0035613941732294332 0.004041675427823353 -0.9999854905603777 1.6970180148754157
  children [
    DEF ModelPanoCamera Transform {
      translation 0 0 -0.003
      children [
        DEF kogeto Transform {
          children [
            DEF len Transform {
              translation 0 0 0.046
              rotation 0.5773522691882489 0.5773502691873165 0.5773482691863839 2.0944
              children [
                CadShape {
                  url [
                    "../3D-models/kogeto-p2.obj"
                  ]
                  castShadows FALSE
                }
              ]
            }
            DEF b Transform {
              translation 0 0 0.042
              children [
                Shape {
                  appearance PBRAppearance {
                    baseColor 0 0 0
                    roughness 0.7
                    metalness 0
                  }
                  geometry Cylinder {
                    height 0.008
                    radius 0.017
                  }
                }
              ]
            }
            DEF t Transform {
              translation 0 0 0.06
              children [
                Shape {
                  appearance PBRAppearance {
                    baseColor 0 0 0
                    roughness 0.7
                    metalness 0
                  }
                  geometry Cylinder {
                    height 0.001
                    radius 0.012
                  }
                }
              ]
            }
          ]
        }
        DEF CamHolder Transform {
          translation 0 0 0.034
          rotation 3.3905113482557537e-09 0.70710528118436 0.707108281185553 3.14159
          children [
            CadShape {
              url [
                "../3D-models/PanoColiasOldHolder.obj"
              ]
            }
          ]
        }
      ]
    }
    DEF Copper Transform {
      children [
        Transform {
          translation -0.0141 0.0112 0.0154
          children [
            DEF screw Transform {
              translation 0 -0.0067 0.01
              scale 0.4 0.4 0.4
              children [
                CadShape {
                  url [
                    "../3D-models/screw.obj"
                  ]
                }
              ]
            }
            Shape {
              appearance Appearance {
                material Material {
                }
                texture ImageTexture {
                  url [
                    "texture/COPPER.jpg"
                  ]
                }
                textureTransform TextureTransform {
                  scale 20 20
                }
              }
              geometry Cylinder {
                height 0.021
                radius 0.001
              }
            }
          ]
        }
        Transform {
          translation 0.0081 -0.016 0.0154
          children [
            DEF screw Transform {
              translation 0 -0.0067 0.01
              scale 0.4 0.4 0.4
              children [
                CadShape {
                  url [
                    "../3D-models/screw.obj"
                  ]
                }
              ]
            }
            Shape {
              appearance Appearance {
                material Material {
                }
                texture ImageTexture {
                  url [
                    "texture/COPPER.jpg"
                  ]
                }
                textureTransform TextureTransform {
                  scale 20 20
                }
              }
              geometry Cylinder {
                height 0.021
                radius 0.001
              }
            }
          ]
        }
      ]
    }
    DEF Right HingeJoint {
      jointParameters HingeJointParameters {
        position 33.34400003329697
        axis -1 0 0
        anchor 0.024 -0.003 0.01
      }
      device [
        RotationalMotor {
          name "MotorRight"
        }
      ]
      endPoint Solid {
        translation 1.3877787807814457e-17 -0.013417699288044094 0.010686688826096375
        rotation 1 0 0 4.3551118097805475
        children [
          DEF RightWheel Transform {
            translation 0.022 -0.003 0.01
            children [
              Transform {
                scale 0.01 0.01 0.01
                children [
                  CadShape {
                    url [
                      "../3D-models/colias_wheel.obj"
                    ]
                  }
                ]
              }
            ]
          }
        ]
        boundingObject Transform {
          translation 0.024 -0.003 0.01
          rotation 0 1 0 -1.5707953071795862
          children [
            Cylinder {
              height 0.002
              radius 0.01
            }
          ]
        }
        physics Physics {
        }
        linearVelocity 0.0003949868794280232 -3.817718841502433e-05 -2.0942684773002193e-09
        angularVelocity 8.68923852785755e-08 -3.50092124128079e-08 -0.40009810514321753
      }
    }
    DEF Left HingeJoint {
      jointParameters HingeJointParameters {
        position 165.31094048661515
        axis -1 0 0
        anchor -0.024 -0.003 0.01
      }
      device [
        DEF MotorLeft RotationalMotor {
          name "MotorLeft"
        }
      ]
      endPoint Solid {
        translation -4.163336342344337e-17 -0.01340183909222593 0.010895401306365241
        rotation -1 0 0 1.9481224999459037
        children [
          DEF LeftWheel Transform {
            translation -0.026 -0.003 0.01
            children [
              Transform {
                scale 0.01 0.01 0.01
                children [
                  CadShape {
                    url [
                      "../3D-models/colias_wheel.obj"
                    ]
                  }
                ]
              }
            ]
          }
        ]
        name "solid(1)"
        boundingObject Transform {
          translation -0.024 -0.003 0.01
          rotation 0 1 0 -1.5707953071795862
          children [
            Cylinder {
              height 0.002
              radius 0.01
            }
          ]
        }
        physics Physics {
        }
        linearVelocity 0.01946938963455936 -0.0023356191742566388 1.796198731284753e-09
        angularVelocity 0.23786220698571342 1.9858389375723284 -0.403816044608978
      }
    }
    DEF ModelMotorR Transform {
      children [
        Transform {
          translation 0 -0.0031 0.0098
          scale 0.1 0.1 0.1
          children [
            CadShape {
              url [
                "../3D-models/motor.obj"
              ]
            }
          ]
        }
      ]
    }
    DEF ModelMotorL Transform {
      rotation 0 1 0 3.14159
      children [
        Transform {
          translation 0.001 -0.0031 -0.01
          scale 0.1 0.1 0.1
          children [
            CadShape {
              url [
                "../3D-models/motor.obj"
              ]
            }
          ]
        }
      ]
    }
    DEF SenseBoard Transform {
      translation 0 0 0.0061
      children [
        Camera {
          translation 0 0 0.0384
          rotation -0.5773509358554485 0.5773489358556708 -0.5773509358554485 -2.094395307179586
          fieldOfView 3.14
          projection "spherical"
          near 0.02
        }
        DEF PCB Transform {
          translation 0 0 0.02
          children [
            CadShape {
              url [
                "../3D-models/V_COLIAS-III_5th.obj"
              ]
            }
          ]
        }
      ]
    }
    DEF BottomBoard Transform {
      translation 0 0 0.0065
      children [
        CadShape {
          url [
            "../3D-models/CBIIIP2_5ath.obj"
          ]
        }
      ]
    }
  ]
  boundingObject Transform {
    translation 0 0 0.0142
    children [
      Shape {
        geometry Cylinder {
          height 0.028
          radius 0.021
        }
      }
    ]
  }
  physics Physics {
  }
  controller "Colias"
  linearVelocity 0.009787082008304216 -0.002392507407047783 -7.765224143395244e-11
  angularVelocity 7.868004254729609e-08 -3.4473167004041986e-08 -0.400098105445212
}
