#VRML_SIM R2023a utf8

EXTERNPROTO "https://raw.githubusercontent.com/cyberbotics/webots/R2023a/projects/objects/backgrounds/protos/TexturedBackground.proto"
EXTERNPROTO "https://raw.githubusercontent.com/cyberbotics/webots/R2023a/projects/objects/backgrounds/protos/TexturedBackgroundLight.proto"
EXTERNPROTO "https://raw.githubusercontent.com/cyberbotics/webots/R2023a/projects/objects/floors/protos/RectangleArena.proto"

WorldInfo {
  contactProperties [
    ContactProperties {
      coulombFriction [
        3
      ]
    }
  ]
}
Viewpoint {
  orientation 0.12750273117411118 0.904849885885285 -0.40618928784069264 0.6678132704917492
  position -1.9178220345421342 0.53587801560279 1.373805831189071
}
TexturedBackground {
}
TexturedBackgroundLight {
}
RectangleArena {
}
Robot {
  translation 0 0 0.0021444
  rotation -0.9999999999996493 -1.4760160182759916e-07 -8.242542813678873e-07 0.0080827841966268
  children [
    Transform {
    }
    DEF Copper Transform {
      children [
        Transform {
          translation -0.0141 0.0112 0.0154
          children [
            DEF screw Transform {
              translation 0 -0.0067 0.01
              scale 0.4 0.4 0.4
              children [
                CadShape {
                  url [
                    "../3D-models/screw.obj"
                  ]
                }
              ]
            }
            Shape {
              appearance Appearance {
                material Material {
                }
                texture ImageTexture {
                  url [
                    "texture/COPPER.jpg"
                  ]
                }
                textureTransform TextureTransform {
                  scale 20 20
                }
              }
              geometry Cylinder {
                height 0.021
                radius 0.001
              }
            }
          ]
        }
        Transform {
          translation 0.0081 -0.016 0.0154
          children [
            DEF screw Transform {
              translation 0 -0.0067 0.01
              scale 0.4 0.4 0.4
              children [
                CadShape {
                  url [
                    "../3D-models/screw.obj"
                  ]
                }
              ]
            }
            Shape {
              appearance Appearance {
                material Material {
                }
                texture ImageTexture {
                  url [
                    "texture/COPPER.jpg"
                  ]
                }
                textureTransform TextureTransform {
                  scale 20 20
                }
              }
              geometry Cylinder {
                height 0.021
                radius 0.001
              }
            }
          ]
        }
      ]
    }
    DEF Right HingeJoint {
      jointParameters HingeJointParameters {
        position 25.791999906596175
        axis -1 0 0
        anchor 0.024 -0.003 0.01
      }
      device [
        RotationalMotor {
          name "MotorRight"
        }
      ]
      endPoint Solid {
        translation 3.469446951953614e-18 -0.006753970855566177 0.00025794155141945115
        rotation -1 0 0 0.6592586778778289
        children [
          DEF RightWheel Transform {
            translation 0.022 -0.003 0.01
            children [
              Transform {
                scale 0.01 0.01 0.01
                children [
                  CadShape {
                    url [
                      "../3D-models/colias_wheel.obj"
                    ]
                  }
                ]
              }
            ]
          }
        ]
        boundingObject Transform {
          translation 0.024 -0.003 0.01
          rotation 0 1 0 -1.5707953071795862
          children [
            Cylinder {
              height 0.002
              radius 0.01
            }
          ]
        }
        physics Physics {
        }
      }
    }
    DEF Left HingeJoint {
      jointParameters HingeJointParameters {
        position 25.79199990655744
        axis -1 0 0
        anchor -0.024 -0.003 0.01
      }
      device [
        DEF MotorLeft RotationalMotor {
          name "MotorLeft"
        }
      ]
      endPoint Solid {
        translation 0 -0.006753970855189589 0.00025794155127433285
        rotation -0.9999999999999999 0 0 0.6592586778390932
        children [
          DEF LeftWheel Transform {
            translation -0.026 -0.003 0.01
            children [
              Transform {
                scale 0.01 0.01 0.01
                children [
                  CadShape {
                    url [
                      "../3D-models/colias_wheel.obj"
                    ]
                  }
                ]
              }
            ]
          }
        ]
        name "solid(1)"
        boundingObject Transform {
          translation -0.024 -0.003 0.01
          rotation 0 1 0 -1.5707953071795862
          children [
            Cylinder {
              height 0.002
              radius 0.01
            }
          ]
        }
        physics Physics {
        }
      }
    }
    Transform {
      children [
        Transform {
          translation 0 -0.0031 0.0098
          scale 0.1 0.1 0.1
          children [
            CadShape {
              url [
                "../3D-models/motor.obj"
              ]
            }
          ]
        }
      ]
    }
    Transform {
      rotation 0 1 0 3.14159
      children [
        Transform {
          translation 0.001 -0.0031 -0.01
          scale 0.1 0.1 0.1
          children [
            CadShape {
              url [
                "../3D-models/motor.obj"
              ]
            }
          ]
        }
      ]
    }
    DEF SenseBoard Transform {
      translation 0 0 0.0061
      children [
        Transform {
          translation 0 0 0.0188
          rotation 0 0 1 3.14159
          scale 0.01 0.01 0.01
          children [
            CadShape {
              url [
                "../3D-models/colias_camera.obj"
              ]
            }
          ]
        }
        Camera {
          translation 0 0.0133 0.0096
          rotation 0 0 1 1.5708
        }
        Transform {
        }
        Transform {
          translation 0 0 0.02
          children [
            CadShape {
              url [
                "../3D-models/V_COLIAS-III_5th.obj"
              ]
            }
          ]
        }
      ]
    }
    DEF BottomBoard Transform {
      translation 0 0 0.0065
      children [
        CadShape {
          url [
            "../3D-models/CBIIIP2_5ath.obj"
          ]
        }
      ]
    }
  ]
  boundingObject Transform {
    translation 0 0 0.0142
    children [
      Shape {
        geometry Cylinder {
          height 0.028
          radius 0.021
        }
      }
    ]
  }
  physics Physics {
  }
  controller "Colias"
}
